test_delete_queue (__main__.TestExercice) ... FAIL
test_delete_stack (__main__.TestExercice) ... FAIL
test_reverse (__main__.TestExercice) ... ERROR
test_sort_queue (__main__.TestExercice) ... FAIL
test_sort_stack (__main__.TestExercice) ... FAIL
test_string_and_structs (__main__.TestExercice) ... ERROR

======================================================================
ERROR: test_reverse (__main__.TestExercice)
----------------------------------------------------------------------
Traceback (most recent call last):
  File "test_exercice.py", line 17, in test_reverse
    output = exercice.reverse_data(values)
  File "/home/runner/work/c03_ch6_exercices-2-Zabiullah-sz/c03_ch6_exercices-2-Zabiullah-sz/exercice.py", line 12, in reverse_data
    lifo = LifoQueue()
NameError: name 'LifoQueue' is not defined

======================================================================
ERROR: test_string_and_structs (__main__.TestExercice)
----------------------------------------------------------------------
Traceback (most recent call last):
  File "test_exercice.py", line 91, in test_string_and_structs
    fifo.put_many("Yeet")
TypeError: put_many() missing 1 required positional argument: 'items'

======================================================================
FAIL: test_delete_queue (__main__.TestExercice)
----------------------------------------------------------------------
Traceback (most recent call last):
  File "test_exercice.py", line 53, in test_delete_queue
    'Mauvaise reponse'
AssertionError: [] != [1, 2, 3, 4, 5, 6, 7, 8, 9, 10, 11, 12, 13, 14, 15, 16, 17, 18, 19] : Mauvaise reponse

======================================================================
FAIL: test_delete_stack (__main__.TestExercice)
----------------------------------------------------------------------
Traceback (most recent call last):
  File "test_exercice.py", line 38, in test_delete_stack
    'Mauvaise reponse'
AssertionError: [] != [0, 1, 2, 3, 4, 5, 6, 7, 8, 9, 10, 11, 12, 13, 14, 15, 16, 17, 18] : Mauvaise reponse

======================================================================
FAIL: test_sort_queue (__main__.TestExercice)
----------------------------------------------------------------------
Traceback (most recent call last):
  File "test_exercice.py", line 83, in test_sort_queue
    'Mauvaise reponse'
AssertionError: [] != [45, 57, 151, 178, 237, 254, 305, 325, 418[51 chars] 931] : Mauvaise reponse

======================================================================
FAIL: test_sort_stack (__main__.TestExercice)
----------------------------------------------------------------------
Traceback (most recent call last):
  File "test_exercice.py", line 68, in test_sort_stack
    'Mauvaise reponse'
AssertionError: [] != [13, 16, 128, 156, 330, 331, 386, 392, 526[51 chars] 988] : Mauvaise reponse

----------------------------------------------------------------------
Ran 6 tests in 0.002s

FAILED (failures=4, errors=2)
